<mujoco>
	<compiler angle="radian" autolimits="true"/>
	<visual>
		<headlight ambient="0.5 0.5 0.5" />
	</visual>
	<option timestep="0.001" integrator="RK4" >
		<flag sensornoise="enable" energy="enable" contact="enable" />
	</option>
	<worldbody>
        <light diffuse=".5 .5 .5" pos="0 0 3" dir="0 0 -1"/>
		<geom type="plane" size="2 1 0.1" rgba=".9 0 0 1"/>
		<body name="hip3" pos="-0.2263 -0.07 0">
      <inertial pos="0 0 0" quat="0.5 0.5 -0.5 0.5" mass="0.575" diaginertia="0.000869688 0.000669635 0.000669635"/>
      <joint name="joint_11" pos="0 0 0" axis="1 0 0" limited="true" range="-1.5707 1.5707"/>
      <geom size="0.055 0.04" pos="0 -0.028 0" quat="0.707107 0.707107 0 0" type="cylinder" contype="0" conaffinity="0" group="1" density="0" rgba="0.68 0.34 0.08 1"/>
      <geom size="0.055 0.04" pos="0 -0.028 0" quat="0.707107 0.707107 0 0" type="cylinder" rgba="0.68 0.34 0.08 1"/>
      <body name="upper3" pos="0 -0.10098 0">
        <inertial pos="0 0 0" quat="0.5 0.5 0.5 0.5" mass="0.775" diaginertia="0.001 0.001 5e-05"/>
        <joint name="joint_6" pos="0 0 0" axis="0 -1 0" limited="true" range="-6.28319 6.28319"/>
        <geom size="0.103 0.011 0.0275" pos="-0.103 0.022 0" type="box" contype="0" conaffinity="0" group="1" density="0" rgba="0.68 0.68 0.68 1"/>
        <geom size="0.103 0.011 0.0275" pos="-0.103 0.022 0" type="box" rgba="0.68 0.68 0.68 1"/>
        <body name="lower3" pos="-0.206 0 0">
          <inertial pos="0.0343333 0 0" quat="0.5 0.5 0.5 0.5" mass="0.09" diaginertia="0.00065545 0.00065545 3e-05"/>
          <joint name="joint_7" pos="0 0 0" axis="0 1 0" limited="true" range="-3 3"/>
          <geom size="0.013 0.103" pos="0.103 0 0" quat="0.707107 0 0.707107 0" type="cylinder" contype="0" conaffinity="0" group="1" density="0" rgba="0.68 0.68 0.68 1"/>
          <geom size="0.013 0.103" pos="0.103 0 0" quat="0.707107 0 0.707107 0" type="cylinder" rgba="0.68 0.68 0.68 1"/>
          <geom size="0.02" pos="0.206 0 0" contype="0" conaffinity="0" group="1" density="0" rgba="0.1 0.1 0.1 1"/>
          <geom size="0.02" pos="0.206 0 0" rgba="0.1 0.1 0.1 1"/>
        </body>
      </body>
    </body>
	</worldbody>
	
	
</mujoco>