<mujoco model="spirit">
  <compiler angle="radian" autolimits="true"/>
  <visual>
		<headlight ambient="0.7 0.7 0.7" />
	</visual>
  <worldbody>
    <geom size="0.08375 0.12 0.052" pos="-0.08375 0 0" type="box" contype="0" conaffinity="0" group="1" density="0" rgba="0.25 0.25 0.25 0.5"/>
    <geom size="0.08375 0.12 0.052" pos="-0.08375 0 0" type="box" rgba="0.25 0.25 0.25 0.5"/>
    <geom size="0.015 0.03 0.03" pos="-0.03 0 0.08" type="box" contype="0" conaffinity="0" group="1" density="0" rgba="0.8 0.8 0 1"/>
    <geom size="0.015 0.03 0.03" pos="-0.03 0 0.08" type="box" rgba="0.8 0.8 0 1"/>
    <geom size="0.055 0.02" pos="-0.18925 0.073 0" quat="0.707107 0 0.707107 0" type="cylinder" contype="0" conaffinity="0" group="1" density="0" rgba="0.8 0.8 0.8 1"/>
    <geom size="0.055 0.02" pos="-0.18925 0.073 0" quat="0.707107 0 0.707107 0" type="cylinder" rgba="0.8 0.8 0.8 1"/>
    <geom size="0.055 0.02" pos="-0.18925 -0.073 0" quat="0.707107 0 0.707107 0" type="cylinder" contype="0" conaffinity="0" group="1" density="0" rgba="0.8 0.8 0.8 1"/>
    <geom size="0.055 0.02" pos="-0.18925 -0.073 0" quat="0.707107 0 0.707107 0" type="cylinder" rgba="0.8 0.8 0.8 1"/>
    <body name="hip1" pos="-0.26925 0.095 0">
      <inertial pos="0 -0.03 0" quat="0.5 0.5 -0.5 0.5" mass="1.15" diaginertia="0.00277437 0.00237427 0.00133927"/>
      <joint name="joint_9" pos="0 0 0" axis="1 0 0" range="-0.707 0.707"/>
      <geom size="0.055 0.02" pos="0 0.028 0" quat="0.707107 0.707107 0 0" type="cylinder" contype="0" conaffinity="0" group="1" density="0" rgba="0.8 0.8 0 1"/>
      <geom size="0.055 0.02" pos="0 0.028 0" quat="0.707107 0.707107 0 0" type="cylinder" rgba="0.8 0.8 0 1"/>
      <geom size="0.055 0.02" pos="0 -0.032 0" quat="0.707107 0.707107 0 0" type="cylinder" contype="0" conaffinity="0" group="1" density="0" rgba="0.8 0.8 0.8 1"/>
      <geom size="0.055 0.02" pos="0 -0.032 0" quat="0.707107 0.707107 0 0" type="cylinder" rgba="0.8 0.8 0.8 1"/>
      <body name="upper1" pos="0 0.06 0">
        <inertial pos="0 0 0" quat="0.5 0.5 0.5 0.5" mass="0.775" diaginertia="0.001 0.001 5e-05"/>
        <joint name="joint_2" pos="0 0 0" axis="0 -1 0" range="-6.28319 6.28319"/>
        <geom size="0.103 0.011 0.0275" pos="-0.103 0 0" type="box" contype="0" conaffinity="0" group="1" density="0" rgba="0.68 0.68 0.68 1"/>
        <geom size="0.103 0.011 0.0275" pos="-0.103 0 0" type="box" rgba="0.68 0.68 0.68 1"/>
        <body name="lower1" pos="-0.206 0 0">
          <inertial pos="0.0343333 0 0" quat="0.5 0.5 0.5 0.5" mass="0.09" diaginertia="0.00087545 0.00056395 0.000345"/>
          <joint name="joint_3" pos="0 0 0" axis="0 1 0" range="0 3.14159"/>
          <geom size="0.013 0.103" pos="0.103 0 0" quat="0.707107 0 0.707107 0" type="cylinder" contype="0" conaffinity="0" group="1" density="0" rgba="0.68 0.68 0.68 1"/>
          <geom size="0.013 0.103" pos="0.103 0 0" quat="0.707107 0 0.707107 0" type="cylinder" rgba="0.68 0.68 0.68 1"/>
          <geom size="0.02" pos="0.206 0 0" contype="0" conaffinity="0" group="1" density="0" rgba="0.1 0.1 0.1 1"/>
          <geom size="0.02" pos="0.206 0 0" rgba="0.1 0.1 0.1 1"/>
        </body>
      </body>
    </body>
    <body name="hip3" pos="-0.26925 -0.095 0">
      <inertial pos="0 0.03 0" quat="0.5 0.5 -0.5 0.5" mass="1.15" diaginertia="0.00277437 0.00237427 0.00133927"/>
      <joint name="joint_11" pos="0 0 0" axis="1 0 0" range="-0.707 0.707"/>
      <geom size="0.055 0.02" pos="0 -0.028 0" quat="0.707107 0.707107 0 0" type="cylinder" contype="0" conaffinity="0" group="1" density="0" rgba="0.8 0.8 0 1"/>
      <geom size="0.055 0.02" pos="0 -0.028 0" quat="0.707107 0.707107 0 0" type="cylinder" rgba="0.8 0.8 0 1"/>
      <geom size="0.055 0.02" pos="0 0.032 0" quat="0.707107 0.707107 0 0" type="cylinder" contype="0" conaffinity="0" group="1" density="0" rgba="0.8 0.8 0.8 1"/>
      <geom size="0.055 0.02" pos="0 0.032 0" quat="0.707107 0.707107 0 0" type="cylinder" rgba="0.8 0.8 0.8 1"/>
      <body name="upper3" pos="0 -0.06 0">
        <inertial pos="0 0 0" quat="0.5 0.5 0.5 0.5" mass="0.775" diaginertia="0.001 0.001 5e-05"/>
        <joint name="joint_6" pos="0 0 0" axis="0 -1 0" range="-6.28319 6.28319"/>
        <geom size="0.103 0.011 0.0275" pos="-0.103 0 0" type="box" contype="0" conaffinity="0" group="1" density="0" rgba="0.68 0.68 0.68 1"/>
        <geom size="0.103 0.011 0.0275" pos="-0.103 0 0" type="box" rgba="0.68 0.68 0.68 1"/>
        <body name="lower3" pos="-0.206 0 0">
          <inertial pos="0.0343333 0 0" quat="0.5 0.5 0.5 0.5" mass="0.09" diaginertia="0.00087545 0.00056395 0.000345"/>
          <joint name="joint_7" pos="0 0 0" axis="0 1 0" range="0 3.14159"/>
          <geom size="0.013 0.103" pos="0.103 0 0" quat="0.707107 0 0.707107 0" type="cylinder" contype="0" conaffinity="0" group="1" density="0" rgba="0.68 0.68 0.68 1"/>
          <geom size="0.013 0.103" pos="0.103 0 0" quat="0.707107 0 0.707107 0" type="cylinder" rgba="0.68 0.68 0.68 1"/>
          <geom size="0.02" pos="0.206 0 0" contype="0" conaffinity="0" group="1" density="0" rgba="0.1 0.1 0.1 1"/>
          <geom size="0.02" pos="0.206 0 0" rgba="0.1 0.1 0.1 1"/>
        </body>
      </body>
    </body>
    <body name="front_body" pos="0.08375 0 0">
      <inertial pos="0.0314738 0 0" quat="0.5 0.5 -0.5 0.5" mass="4.356" diaginertia="0.0373172 0.022988 0.0225184"/>
      <joint name="joint_12" pos="0 0 0" axis="1 0 0" range="-0.707 0.707"/>
      <geom size="0.08375 0.12 0.052" type="box" contype="0" conaffinity="0" group="1" density="0" rgba="0.25 0.25 0.25 0.5"/>
      <geom size="0.08375 0.12 0.052" type="box" rgba="0.25 0.25 0.25 0.5"/>
      <geom size="0.03 0.075 0.02" pos="0.025 0 -0.02" type="box" contype="0" conaffinity="0" group="1" density="0" rgba="0.8 0.8 0 1"/>
      <geom size="0.03 0.075 0.02" pos="0.025 0 -0.02" type="box" rgba="0.8 0.8 0 1"/>
      <geom size="0.055 0.02" pos="0.1055 0.073 0" quat="0.707107 0 0.707107 0" type="cylinder" contype="0" conaffinity="0" group="1" density="0" rgba="0.8 0.8 0.8 1"/>
      <geom size="0.055 0.02" pos="0.1055 0.073 0" quat="0.707107 0 0.707107 0" type="cylinder" rgba="0.8 0.8 0.8 1"/>
      <geom size="0.055 0.02" pos="0.1055 -0.073 0" quat="0.707107 0 0.707107 0" type="cylinder" contype="0" conaffinity="0" group="1" density="0" rgba="0.8 0.8 0.8 1"/>
      <geom size="0.055 0.02" pos="0.1055 -0.073 0" quat="0.707107 0 0.707107 0" type="cylinder" rgba="0.8 0.8 0.8 1"/>
      <body name="hip0" pos="0.1855 0.095 0">
        <inertial pos="0 -0.03 0" quat="0.5 0.5 -0.5 0.5" mass="1.15" diaginertia="0.00277437 0.00237427 0.00133927"/>
        <joint name="joint_8" pos="0 0 0" axis="1 0 0" range="-0.707 0.707"/>
        <geom size="0.055 0.02" pos="0 0.028 0" quat="0.707107 0.707107 0 0" type="cylinder" contype="0" conaffinity="0" group="1" density="0" rgba="0.8 0.8 0 1"/>
        <geom size="0.055 0.02" pos="0 0.028 0" quat="0.707107 0.707107 0 0" type="cylinder" rgba="0.8 0.8 0 1"/>
        <geom size="0.055 0.02" pos="0 -0.032 0" quat="0.707107 0.707107 0 0" type="cylinder" contype="0" conaffinity="0" group="1" density="0" rgba="0.8 0.8 0.8 1"/>
        <geom size="0.055 0.02" pos="0 -0.032 0" quat="0.707107 0.707107 0 0" type="cylinder" rgba="0.8 0.8 0.8 1"/>
        <body name="upper0" pos="0 0.06 0">
          <inertial pos="0 0 0" quat="0.5 0.5 0.5 0.5" mass="0.775" diaginertia="0.001 0.001 5e-05"/>
          <joint name="joint_0" pos="0 0 0" axis="0 -1 0" range="-6.28319 6.28319"/>
          <geom size="0.103 0.011 0.0275" pos="-0.103 0 0" type="box" contype="0" conaffinity="0" group="1" density="0" rgba="0.68 0.68 0.68 1"/>
          <geom size="0.103 0.011 0.0275" pos="-0.103 0 0" type="box" rgba="0.68 0.68 0.68 1"/>
          <body name="lower0" pos="-0.206 0 0">
            <inertial pos="0.0343333 0 0" quat="0.5 0.5 0.5 0.5" mass="0.09" diaginertia="0.00087545 0.00056395 0.000345"/>
            <joint name="joint_1" pos="0 0 0" axis="0 1 0" range="0 3.14159"/>
            <geom size="0.013 0.103" pos="0.103 0 0" quat="0.707107 0 0.707107 0" type="cylinder" contype="0" conaffinity="0" group="1" density="0" rgba="0.68 0.68 0.68 1"/>
            <geom size="0.013 0.103" pos="0.103 0 0" quat="0.707107 0 0.707107 0" type="cylinder" rgba="0.68 0.68 0.68 1"/>
            <geom size="0.02" pos="0.206 0 0" contype="0" conaffinity="0" group="1" density="0" rgba="0.1 0.1 0.1 1"/>
            <geom size="0.02" pos="0.206 0 0" rgba="0.1 0.1 0.1 1"/>
          </body>
        </body>
      </body>
      <body name="hip2" pos="0.1855 -0.095 0">
        <inertial pos="0 0.03 0" quat="0.5 0.5 -0.5 0.5" mass="1.15" diaginertia="0.00277437 0.00237427 0.00133927"/>
        <joint name="joint_10" pos="0 0 0" axis="1 0 0" range="-0.707 0.707"/>
        <geom size="0.055 0.02" pos="0 -0.028 0" quat="0.707107 0.707107 0 0" type="cylinder" contype="0" conaffinity="0" group="1" density="0" rgba="0.8 0.8 0 1"/>
        <geom size="0.055 0.02" pos="0 -0.028 0" quat="0.707107 0.707107 0 0" type="cylinder" rgba="0.8 0.8 0 1"/>
        <geom size="0.055 0.02" pos="0 0.032 0" quat="0.707107 0.707107 0 0" type="cylinder" contype="0" conaffinity="0" group="1" density="0" rgba="0.8 0.8 0.8 1"/>
        <geom size="0.055 0.02" pos="0 0.032 0" quat="0.707107 0.707107 0 0" type="cylinder" rgba="0.8 0.8 0.8 1"/>
        <body name="upper2" pos="0 -0.06 0">
          <inertial pos="0 0 0" quat="0.5 0.5 0.5 0.5" mass="0.775" diaginertia="0.001 0.001 5e-05"/>
          <joint name="joint_4" pos="0 0 0" axis="0 -1 0" range="-6.28319 6.28319"/>
          <geom size="0.103 0.011 0.0275" pos="-0.103 0 0" type="box" contype="0" conaffinity="0" group="1" density="0" rgba="0.68 0.68 0.68 1"/>
          <geom size="0.103 0.011 0.0275" pos="-0.103 0 0" type="box" rgba="0.68 0.68 0.68 1"/>
          <body name="lower2" pos="-0.206 0 0">
            <inertial pos="0.0343333 0 0" quat="0.5 0.5 0.5 0.5" mass="0.09" diaginertia="0.00087545 0.00056395 0.000345"/>
            <joint name="joint_5" pos="0 0 0" axis="0 1 0" range="0 3.14159"/>
            <geom size="0.013 0.103" pos="0.103 0 0" quat="0.707107 0 0.707107 0" type="cylinder" contype="0" conaffinity="0" group="1" density="0" rgba="0.68 0.68 0.68 1"/>
            <geom size="0.013 0.103" pos="0.103 0 0" quat="0.707107 0 0.707107 0" type="cylinder" rgba="0.68 0.68 0.68 1"/>
            <geom size="0.02" pos="0.206 0 0" contype="0" conaffinity="0" group="1" density="0" rgba="0.1 0.1 0.1 1"/>
            <geom size="0.02" pos="0.206 0 0" rgba="0.1 0.1 0.1 1"/>
          </body>
        </body>
      </body>
    </body>
  </worldbody>
</mujoco>
