<mujoco model="spirit">
  <compiler angle="radian" autolimits="true"/>
  
  <option timestep="0.001" integrator="Euler" gravity="0 0 -9.81" > 
	<!-- https://github.com/deepmind/mujoco/issues/941 -->
		<flag sensornoise="enable" energy="enable" contact="enable" />
	</option>
  <visual>
		<headlight ambient="0.3 0.3 0.3" />
	</visual>
  <worldbody>
    <geom type="plane" size="1 1 0.1" rgba="0.9 0 0 1" pos="0 0 0" contype="4" conaffinity="8"/>
    <body name="ROBOT BODY" >
      <!-- <joint type="free"/> -->
			<joint name="z" type="slide"  axis="0 0 1" />
      <joint name="x" type="hinge" pos="0 0 0"  axis="1 0 0" />
      <!-- solimplimit=".95 .99 1e-3" tightening joint limits -->
      <geom size="0.08375 0.12 0.052" type="box" contype="0" conaffinity="0" group="1" density="1000" rgba="0.25 0.25 0.25 0.5"/>
      

      <!-- <geom size="0.015 0.03 0.03" pos="0.05375 0 0.08" type="box" contype="0" conaffinity="0" group="1" density="0" rgba="0.8 0.8 0 1"/> -->
      <geom size="0.055 0.02" pos="-0.1055 0.073 0" quat="0.707107 0 0.707107 0" type="cylinder" contype="0" conaffinity="0" group="1" density="1000" rgba="0.8 0.8 0.8 1"/>
      <geom size="0.055 0.02" pos="-0.1055 -0.073 0" quat="0.707107 0 0.707107 0" type="cylinder" contype="0" conaffinity="0" group="1" density="1000" rgba="0.8 0.8 0.8 1"/>

      <body name="front_body">
        <joint name="spine" axis="1 0 0" range="-2.54 2.54"/>
        <geom size="0.08375 0.12 0.052" pos="0.1675 0 0" type="box" contype="0" conaffinity="0" group="1" density="1000" rgba="0.25 0.25 0.25 0.5"/>
        <geom size="0.03 0.075 0.02" pos="0.1925 0 -0.02" type="box" contype="0" conaffinity="0" group="1" density="1000" rgba="0.8 0.8 0 1"/>
        <geom size="0.055 0.02" pos="0.273 0.073 0" quat="0.707107 0 0.707107 0" type="cylinder" contype="0" conaffinity="0" group="1" density="1000" rgba="0.8 0.8 0.8 1"/>
        <geom size="0.055 0.02" pos="0.273 -0.073 0" quat="0.707107 0 0.707107 0" type="cylinder" contype="0" conaffinity="0" group="1" density="1000" rgba="0.8 0.8 0.8 1"/>



        <body name="hip0" pos="0.353 0.095 0">
        <inertial pos="0 -0.03 0" quat="0.5 0.5 -0.5 0.5" mass="1.15" diaginertia="0.00277437 0.00237427 0.00133927"/>
        <joint name="joint_8" pos="0 0 0" axis="1 0 0" range="-1.2 1.2"/>
        <geom size="0.055 0.02" pos="0 0.028 0" quat="0.707107 0.707107 0 0" type="cylinder" contype="0" conaffinity="0" group="1" density="0" rgba="0.8 0.8 0 1"/>
        <geom size="0.055 0.02" pos="0 0.028 0" quat="0.707107 0.707107 0 0" type="cylinder" rgba="0.8 0.8 0 1"/>
        <geom size="0.055 0.02" pos="0 -0.032 0" quat="0.707107 0.707107 0 0" type="cylinder" contype="0" conaffinity="0" group="1" density="0" rgba="0.8 0.8 0.8 1"/>
        <geom size="0.055 0.02" pos="0 -0.032 0" quat="0.707107 0.707107 0 0" type="cylinder" rgba="0.8 0.8 0.8 1"/>
        <body name="upper0" pos="0 0.06 0" euler="0 -1.57 0">
          <inertial pos="0 0 0" quat="0.5 0.5 0.5 0.5" mass="0.775" diaginertia="0.001 0.001 5e-05"/>
          <joint name="joint_0" pos="0 0 0" axis="0 1 0" range="-3.1415926 3.1415926" solimplimit=".95 .99 1e-3"/>
          <geom size="0.103 0.011 0.0275" pos="-0.103 0 0" type="box" contype="0" conaffinity="0" group="1" density="0" rgba="0.68 0.68 0.68 1"/>
          <geom size="0.103 0.011 0.0275" pos="-0.103 0 0" type="box" rgba="0.68 0.68 0.68 1"/>
          <body name="lower0" pos="-0.206 0 0" >
            <inertial pos="0.0343333 0 0" quat="0.5 0.5 0.5 0.5" mass="0.09" diaginertia="0.00087545 0.00056395 0.000345"/>
            <joint name="joint_1" pos="0 0 0" axis="0 1 0" range="-2.9 2.9" solimplimit=".95 .99 1e-3"/>
            <geom size="0.013 0.103" pos="-0.103 0 0" quat="0.707107 0 0.707107 0" type="cylinder" contype="1" conaffinity="0" group="1" density="0" rgba="0.68 0.68 0.68 1"/>
            <geom size="0.013 0.103" pos="-0.103 0 0" quat="0.707107 0 0.707107 0" type="cylinder" rgba="0.68 0.68 0.68 1"/>
            <geom size="0.02" pos="-0.206 0 0" condim="1" contype="8" conaffinity="0" group="1" density="0" rgba="0.1 0.1 0.1 1"/>
            
          </body>
        </body>
      </body>

      <body name="hip2" pos="0.353 -0.095 0">
        <inertial pos="0 0.03 0" quat="0.5 0.5 -0.5 0.5" mass="1.15" diaginertia="0.00277437 0.00237427 0.00133927"/>
        <joint name="joint_10" pos="0 0 0" axis="1 0 0" range="-1.2 1.2"/>
        <geom size="0.055 0.02" pos="0 -0.028 0" quat="0.707107 0.707107 0 0" type="cylinder" contype="0" conaffinity="0" group="1" density="0" rgba="0.8 0.8 0 1"/>
        <geom size="0.055 0.02" pos="0 -0.028 0" quat="0.707107 0.707107 0 0" type="cylinder" rgba="0.8 0.8 0 1"/>
        <geom size="0.055 0.02" pos="0 0.032 0" quat="0.707107 0.707107 0 0" type="cylinder" contype="0" conaffinity="0" group="1" density="0" rgba="0.8 0.8 0.8 1"/>
        <geom size="0.055 0.02" pos="0 0.032 0" quat="0.707107 0.707107 0 0" type="cylinder" rgba="0.8 0.8 0.8 1"/>
        <body name="upper2" pos="0 -0.06 0" euler="0 -1.57 0">
          <inertial pos="0 0 0" quat="0.5 0.5 0.5 0.5" mass="0.775" diaginertia="0.001 0.001 5e-05"/>
          <joint name="joint_4" pos="0 0 0" axis="0 1 0" range="-3.1415926 3.1415926"/>
          <geom size="0.103 0.011 0.0275" pos="-0.103 0 0" type="box" contype="0" conaffinity="0" group="1" density="0" rgba="0.68 0.68 0.68 1"/>
          <geom size="0.103 0.011 0.0275" pos="-0.103 0 0" type="box" rgba="0.68 0.68 0.68 1"/>
          <body name="lower2" pos="-0.206 0 0" >
            <inertial pos="0.0343333 0 0" quat="0.5 0.5 0.5 0.5" mass="0.09" diaginertia="0.00087545 0.00056395 0.000345"/>
            <joint name="joint_5" pos="0 0 0" axis="0 1 0" range="-2.9 2.9" solimplimit=".95 .99 1e-3" />
            <geom size="0.013 0.103" pos="-0.103 0 0" quat="0.707107 0 0.707107 0" type="cylinder" contype="1" conaffinity="0" group="1" density="0" rgba="0.68 0.68 0.68 1"/>
            <geom size="0.013 0.103" pos="-0.103 0 0" quat="0.707107 0 0.707107 0" type="cylinder" rgba="0.68 0.68 0.68 1"/>
            <geom size="0.02" pos="-0.206 0 0"  condim="1" contype="8" conaffinity="0" group="1" density="0" rgba="0.1 0.1 0.1 1"/>
          </body>
        </body>
      </body>
      </body>

      

    

    

      
      
      <body name="hip1" pos="-0.1855 0.095 0">
        <inertial pos="0 -0.03 0" quat="0.5 0.5 -0.5 0.5" mass="1.15" diaginertia="0.00277437 0.00237427 0.00133927"/>
        <joint name="joint_9" pos="0 0 0" axis="1 0 0" range="-1.2 1.2"/>
        <geom size="0.055 0.02" pos="0 0.028 0" quat="0.707107 0.707107 0 0" type="cylinder" contype="0" conaffinity="0" group="1" density="0" rgba="0.8 0.8 0 1"/>
        <geom size="0.055 0.02" pos="0 0.028 0" quat="0.707107 0.707107 0 0" type="cylinder" rgba="0.8 0.8 0 1"/>
        <geom size="0.055 0.02" pos="0 -0.032 0" quat="0.707107 0.707107 0 0" type="cylinder" contype="0" conaffinity="0" group="1" density="0" rgba="0.8 0.8 0.8 1"/>
        <geom size="0.055 0.02" pos="0 -0.032 0" quat="0.707107 0.707107 0 0" type="cylinder" rgba="0.8 0.8 0.8 1"/>
        <body name="upper1" pos="0 0.06 0" euler="0 -1.57 0">
          <inertial pos="0 0 0" quat="0.5 0.5 0.5 0.5" mass="0.775" diaginertia="0.001 0.001 5e-05"/>
          <joint name="joint_2" pos="0 0 0" axis="0 1 0" range="-3.1415926 3.1415926"/>
          <geom size="0.103 0.011 0.0275" pos="-0.103 0 0" type="box" contype="0" conaffinity="0" group="1" density="0" rgba="0.68 0.68 0.68 1"/>
          <geom size="0.103 0.011 0.0275" pos="-0.103 0 0" type="box" rgba="0.68 0.68 0.68 1"/>
          <body name="lower1" pos="-0.206 0 0" euler="0 0 0">
            <inertial pos="0.0343333 0 0" quat="0.5 0.5 0.5 0.5" mass="0.09" diaginertia="0.00087545 0.00056395 0.000345"/>
            <joint name="joint_3" pos="0 0 0" axis="0 1 0" range="-2.9 2.9" solimplimit=".95 .99 1e-3"/>
            <geom size="0.013 0.103" pos="-0.103 0 0" quat="0.707107 0 0.707107 0" type="cylinder" contype="1" conaffinity="0" group="1" density="0" rgba="0.68 0.68 0.68 1"/>
            <geom size="0.013 0.103" pos="-0.103 0 0" quat="0.707107 0 0.707107 0" type="cylinder" rgba="0.68 0.68 0.68 1"/>
            <geom size="0.02" pos="-0.206 0 0"  condim="1" contype="8" conaffinity="0" group="1" density="0" rgba="0.1 0.1 0.1 1"/>
          </body>
        </body>
      </body>

      <body name="hip3" pos="-0.1855 -0.095 0">
        <inertial pos="0 0.03 0" quat="0.5 0.5 -0.5 0.5" mass="1.15" diaginertia="0.00277437 0.00237427 0.00133927"/>
        <joint name="joint_11" pos="0 0 0" axis="1 0 0" range="-1.2 1.2"/>
        <geom size="0.055 0.02" pos="0 -0.028 0" quat="0.707107 0.707107 0 0" type="cylinder" contype="0" conaffinity="0" group="1" density="0" rgba="0.8 0.8 0 1"/>
        <geom size="0.055 0.02" pos="0 -0.028 0" quat="0.707107 0.707107 0 0" type="cylinder" rgba="0.8 0.8 0 1"/>
        <geom size="0.055 0.02" pos="0 0.032 0" quat="0.707107 0.707107 0 0" type="cylinder" contype="0" conaffinity="0" group="1" density="0" rgba="0.8 0.8 0.8 1"/>
        <geom size="0.055 0.02" pos="0 0.032 0" quat="0.707107 0.707107 0 0" type="cylinder" rgba="0.8 0.8 0.8 1"/>
        <body name="upper3" pos="0 -0.06 0" euler="0 -1.57 0">
          <inertial pos="0 0 0" quat="0.5 0.5 0.5 0.5" mass="0.775" diaginertia="0.001 0.001 5e-05"/>
          <joint name="joint_6" pos="0 0 0" axis="0 1 0" range="-3.1415926 3.1415926"/>
          <geom size="0.103 0.011 0.0275" pos="-0.103 0 0" type="box" contype="0" conaffinity="0" group="1" density="0" rgba="0.68 0.68 0.68 1"/>
          <geom size="0.103 0.011 0.0275" pos="-0.103 0 0" type="box" rgba="0.68 0.68 0.68 1"/>
          <body name="lower3" pos="-0.206 0 0" euler="0 0 0">
            <inertial pos="0.0343333 0 0" quat="0.5 0.5 0.5 0.5" mass="0.09" diaginertia="0.00087545 0.00056395 0.000345"/>
            <joint name="joint_7" pos="0 0 0" axis="0 1 0" range="-2.9 2.9" solimplimit=".95 .99 1e-3"/>
            <geom size="0.013 0.103" pos="-0.103 0 0" quat="0.707107 0 0.707107 0" type="cylinder" contype="1" conaffinity="0" group="1" density="0" rgba="0.68 0.68 0.68 1"/>
            <geom size="0.013 0.103" pos="-0.103 0 0" quat="0.707107 0 0.707107 0" type="cylinder" rgba="0.68 0.68 0.68 1"/>
            <geom size="0.02" pos="-0.206 0 0"  condim="1" contype="8" conaffinity="0" group="1" density="0" rgba="0.1 0.1 0.1 1"/>
            <!-- <geom size="0.02" pos="-0.206 0 0" rgba="0.1 0.1 0.1 1"/> -->
          </body>
        </body>
      </body>
    </body>
  </worldbody>

  <equality>
    <joint joint1="x" joint2="spine" polycoef="0 -0.5 0 0 0"></joint> 
  </equality>

  <actuator>
		<motor joint="spine" name="Spine Torque"/>

    
		<motor joint="joint_8" name="FL Abductor"/>
    <motor joint="joint_1" name="FL Lower"/>
    <motor joint="joint_0" name="FL Upper"/>

    <motor joint="joint_9" name="RL Abductor"/>
    <motor joint="joint_3" name="RL Lower"/>
    <motor joint="joint_2" name="RL Upper"/>

    <motor joint="joint_10" name="FR Abductor"/>
    <motor joint="joint_5" name="FR Lower"/>
    <motor joint="joint_4" name="FR Upper"/>

    <motor joint="joint_11" name="RR Abductor"/>
    <motor joint="joint_7" name="RR Lower"/>
    <motor joint="joint_6" name="RR Upper"/>
		
	</actuator>
  
</mujoco>
