<?xml version="1.0" ?>

<!--J. D. Caporale <jdcap@seas.upenn.edu>
Editted Gazebo URDF to be used drake and removed unnecessary components
12/22/2020-->
<!--
MIT License (modified)
Copyright (c) 2020 Ghost Robotics
Authors:
Avik De <avik@ghostrobotics.io>
Tom Jacobs <tom.jacobs@ghostrobotics.io>
Permission is hereby granted, free of charge, to any person obtaining a copy
of this **file** (the "Software"), to deal
in the Software without restriction, including without limitation the rights
to use, copy, modify, merge, publish, distribute, sublicense, and/or sell
copies of the Software, and to permit persons to whom the Software is
furnished to do so, subject to the following conditions:
The above copyright notice and this permission notice shall be included in all
copies or substantial portions of the Software.
THE SOFTWARE IS PROVIDED "AS IS", WITHOUT WARRANTY OF ANY KIND, EXPRESS OR
IMPLIED, INCLUDING BUT NOT LIMITED TO THE WARRANTIES OF MERCHANTABILITY,
FITNESS FOR A PARTICULAR PURPOSE AND NONINFRINGEMENT. IN NO EVENT SHALL THE
AUTHORS OR COPYRIGHT HOLDERS BE LIABLE FOR ANY CLAIM, DAMAGES OR OTHER
LIABILITY, WHETHER IN AN ACTION OF CONTRACT, TORT OR OTHERWISE, ARISING FROM,
OUT OF OR IN CONNECTION WITH THE SOFTWARE OR THE USE OR OTHER DEALINGS IN THE
SOFTWARE.
-->
<robot  xmlns:xacro="http://www.ros.org/wiki/xacro" name="spirit">

  <mujoco> <compiler discardvisual="false"/> </mujoco>
  <material name="yellow">
    <color rgba="0.8 0.8 0 1"/>
  </material>
  <material name="black">
    <color rgba="0.1 0.1 0.1 1"/>
  </material>
  <material name="darkgray">
    <color rgba="0.25 0.25 0.25 0.5"/>
  </material>
  <material name="copper">
    <color rgba="0.8 0.8 0.8 1"/>
  </material>
  <material name="silver">
    <color rgba="0.68 0.68 0.68 1"/>
  </material>
  <!--
	leg suffix="0" hipJointName="0" kneeJointName="1" abductionJointName="8"
 	leg suffix="1" hipJointName="2" kneeJointName="3" abductionJointName="9"
 	leg suffix="2" hipJointName="4" kneeJointName="5" abductionJointName="10"
 	leg suffix="3" hipJointName="6" kneeJointName="7" abductionJointName="11"
	-->
  
  <!-- First body segment-->
 

  <xacro:macro name="make_body" params="length width heigth ">
    <!-- First body segment-->
  <link name="body">
	</link>

  <link name="rear_body">
    <visual>
      <origin rpy="0 0 0" xyz="0 0 0"/>
      <geometry>
        <box size="${length} ${width} ${heigth}"/>
      </geometry>
      <material name="darkgray"/>
    </visual>
    <inertial>
      <mass value="2.575"/>
      <!-- Uniform box -->
      <!-- <inertia ixx="1/12*${bodyMass}*(${bodyWidth}*${bodyWidth} + ${bodyHeight}*${bodyHeight})"  ixy="0"  ixz="0" iyy="1/12*${bodyMass}*(${bodyLength}*${bodyLength} + ${bodyHeight}*${bodyHeight})" iyz="0" izz="1/12*${bodyMass}*(${bodyLength}*${bodyLength} + ${bodyWidth}*${bodyWidth})"/> -->
      <inertia ixx="0.017" ixy="0" ixz="0" iyy="0.01" iyz="0" izz="0.021"/>
    </inertial>
    <!-- Just copy geometry for collision -->
    <collision>
      <origin rpy="0 0 0" xyz="0 0 0"/>
      <geometry>
        <box size="${length} ${width} ${heigth}"/>
      </geometry>
    </collision>
  </link>
  
  <!-- Fixed rear body displacement -->
  <joint name="fixed_rear" type="fixed">
    <parent link="body"/>
    <child link="rear_body"/>
    <origin xyz="-0.08375 0 0"/>
  </joint>

  <!-- Second body segment-->
  <link name="front_body">
    <visual>
      <origin rpy="0 0 0" xyz="0 0 0"/>
      <geometry>
        <box size="${length} ${width} ${heigth}"/>
      </geometry>
      <material name="darkgray"/>
    </visual>
    <inertial>
      <mass value="2.575"/>
      <!-- Uniform box -->
      <!-- <inertia ixx="1/12*${bodyMass}*(${bodyWidth}*${bodyWidth} + ${bodyHeight}*${bodyHeight})"  ixy="0"  ixz="0" iyy="1/12*${bodyMass}*(${bodyLength}*${bodyLength} + ${bodyHeight}*${bodyHeight})" iyz="0" izz="1/12*${bodyMass}*(${bodyLength}*${bodyLength} + ${bodyWidth}*${bodyWidth})"/> -->
      <inertia ixx="0.018" ixy="0" ixz="0" iyy="0.012" iyz="0" izz="0.023"/>
    </inertial>
    <!-- Just copy geometry for collision -->
    <collision>
      <origin rpy="0 0 0" xyz="0.0 0 0"/>
      <geometry>
        <box size="${length} ${width} ${heigth}"/>
      </geometry>
    </collision>
  </link>

  </xacro:macro>

 
 <xacro:make_body length="0.1675" width="0.24" heigth="0.104"/>

  <xacro:macro name="spine_hump" >
    <link name="spine-hump">
    <visual>
      <origin rpy="0 0 0" xyz="-0.02 0. 0.08"/>
      <geometry>
        <box size="0.03 0.06 0.06"/> 
      </geometry>
      <material name="yellow"/>
    </visual>
    <collision>
      <origin rpy="0 0 0" xyz="-0.02 0. 0.08"/>
      <geometry>
        <box size="0.03 0.06 0.06"/> 
      </geometry>
    </collision>
    <inertial>
      <mass value="0.575"/>
      <!-- <inertia ixx="1/12*${podMass}*${podLength}*${podLength} + 1/4*${podMass}*${podRadius}*${podRadius}"  ixy="0"  ixz="0" iyy="1/12*${podMass}*${podLength}*${podLength} + 1/4*${podMass}*${podRadius}*${podRadius}" iyz="0" izz="1/2*${podMass}*${podRadius}*$
				{podRadius}" /> -->
      <inertia ixx="0.00076963541" ixy="0" ixz="0" iyy="0.00074963541" iyz="0" izz="0.0009496875"/>  
    </inertial>
   </link>

    <joint name="spine_mot" type="fixed">
        <parent link="rear_body"/>
        <child link="spine-hump"/>
        
        <origin xyz="0.07375 0 0"/>
    </joint>
  </xacro:macro>


  <xacro:spine_hump/>  
  

  <xacro:macro name="battery" >
    <link name="battery">
        <visual>
        <origin rpy="0 0 0" xyz="0 0. -0.02"/>
        <geometry>
            <box size="0.06 0.15 0.04"/>  
        </geometry>
        <material name="yellow"/>
        </visual>
        <collision>
        <origin rpy="0 0 0" xyz="0 0. -0.02"/>
        <geometry>
            <box size="0.06 0.15 0.04"/>  
        </geometry>
        </collision>
        <inertial>
        <mass value="0.631"/>
        <inertia ixx="0.00132" ixy="0" ixz="0" iyy="0.0003" iyz="0" izz="0.00137"/>
        </inertial>
    </link>

    <joint name="battery" type="fixed">
        <parent link="front_body"/>
        <child link="battery"/>
        <axis xyz="1 0 0"/>
        <origin xyz="0.025 0 0"/>
        <limit effort="40" lower="-0.707" upper="0.707" velocity="8"/>
        <dynamics damping="0.0" friction="0.0"/>
    </joint>
  </xacro:macro>


  <xacro:battery/>  

  <xacro:macro name="body_twist" >
        <!-- body twist joint. Joint name: 12 -->
    <joint name="joint_12" type="revolute">
        <parent link="body"/>
        <child link="front_body"/>
        <axis xyz="1 0 0"/>
        <origin xyz="0.08375 0 0"/>
        <limit effort="40" lower="-0.707" upper="0.707" velocity="8"/>
        <dynamics damping="0.0" friction="0.0"/>
    </joint>
    <!-- Transmission elements required for Gazebo -->
    <transmission name="transmission_12">
        <type>transmission_interface/SimpleTransmission</type>
        <joint name="joint_12">
        <!-- <hardwareInterface>hardware_interface/EffortJointInterface</hardwareInterface> -->
        </joint>
        <actuator name="motor_12">
        <!-- <hardwareInterface>EffortJointInterface</hardwareInterface> -->
        <mechanicalReduction>1</mechanicalReduction>
        </actuator>
    </transmission>
  </xacro:macro>  

  <xacro:body_twist/>

  <xacro:macro name="motor_left" params="roll pitch yaw name color ">
     <link name="${name}">
        <visual>
        <origin rpy="${roll} ${pitch} ${yaw}" xyz="0 0.028 0"/>
        <geometry>
            <cylinder length="0.04" radius="0.055"/>    
        </geometry>
        <material name="${color}"/>
        </visual>
        <collision>
        <origin rpy="${roll} ${pitch} ${yaw}" xyz="0 0.028 0"/>
        <geometry>
            <cylinder length="0.04" radius="0.055"/>
        </geometry>
        </collision>
        <inertial>
        <mass value="0.575"/>
        <!-- <inertia ixx="1/12*${podMass}*${podLength}*${podLength} + 1/4*${podMass}*${podRadius}*${podRadius}"  ixy="0"  ixz="0" iyy="1/12*${podMass}*${podLength}*${podLength} + 1/4*${podMass}*${podRadius}*${podRadius}" iyz="0" izz="1/2*${podMass}*${podRadius}*$
                    {podRadius}" /> -->
        <inertia ixx="0.00066963541" ixy="0" ixz="0" iyy="0.00066963541" iyz="0" izz="0.0008696875"/>
        </inertial>
     </link>
  </xacro:macro>

  <xacro:macro name="motor_right" params="roll pitch yaw name color ">
     <link name="${name}">
        <visual>
        <origin rpy="${roll} ${pitch} ${yaw}" xyz="0 -0.028 0"/>
        <geometry>
            <cylinder length="0.04" radius="0.055"/>    
        </geometry>
        <material name="${color}"/>
        </visual>
        <collision>
        <origin rpy="${roll} ${pitch} ${yaw}" xyz="0 -0.028 0"/>
        <geometry>
            <cylinder length="0.04" radius="0.055"/>
        </geometry>
        </collision>
        <inertial>
        <mass value="0.575"/>
        <!-- <inertia ixx="1/12*${podMass}*${podLength}*${podLength} + 1/4*${podMass}*${podRadius}*${podRadius}"  ixy="0"  ixz="0" iyy="1/12*${podMass}*${podLength}*${podLength} + 1/4*${podMass}*${podRadius}*${podRadius}" iyz="0" izz="1/2*${podMass}*${podRadius}*$
                    {podRadius}" /> -->
        <inertia ixx="0.00066963541" ixy="0" ixz="0" iyy="0.00066963541" iyz="0" izz="0.0008696875"/>
        </inertial>
     </link>
  </xacro:macro>

  <xacro:macro name="upper_leg" params="name">
    <!-- Upper leg -->
    <link name="${name}">
        <visual>
        <origin rpy="0 0 0" xyz="-0.103 0 0"/>
        <geometry>
            <box size="0.206 0.022 0.055"/>
        </geometry>
        <material name="silver"/>
        </visual>
        <collision>
        <origin rpy="0 0 0" xyz="-0.103 0 0"/>
        <geometry>
            <box size="0.206 0.022 0.055"/>
        </geometry>
        </collision>
        <inertial>
        <mass value="0.775"/>
        <inertia ixx="5e-05" ixy="0" ixz="0" iyy="0.001" iyz="0" izz="0.001"/>
        </inertial>
    </link>
  </xacro:macro>
  
  
  
  
  <xacro:macro name="lower_leg" params="name">
  <!-- Lower leg -->
    <link name="${name}">
        <visual>
        <origin rpy="0 1.570796326795 0" xyz="0.103 0 0"/>
        <geometry>
            <cylinder length="0.206" radius="0.013"/>
        </geometry>
        <material name="silver"/>
        </visual>
        <collision>
        <origin rpy="0 1.570796326795 0" xyz="0.103 0 0"/>
        <geometry>
            <cylinder length="0.206" radius="0.013"/>
        </geometry>
        </collision>
        <inertial>
        <mass value="0.075"/>
        <inertia ixx="0.00032" ixy="0" ixz="0" iyy="0.00032" iyz="0" izz="0.0000085"/>
        </inertial>
    </link>
  </xacro:macro>
    
  

    <!-- Hip motor -->
    <xacro:motor_left roll= "1.570796326795" pitch="0" yaw="0" name="hip0" color="yellow"/>  
    <!-- Abd motor -->
    <xacro:motor_left pitch= "1.570796326795" roll="0" yaw="0" name="abd0" color="copper"/>  

    <!-- Con motor -->
    <xacro:motor_left roll= "1.570796326795" pitch="0" yaw="0" name="con0" color="copper"/>  

    <xacro:property name="Abd_xf" value="0.1055"/>
    <xacro:property name="Abd_xb" value="-0.1055"/>

    <xacro:property name="Abd_yl" value="0.045"/>
    <xacro:property name="Abd_yr" value="-0.045"/>


    <xacro:property name="Abd2Hip_xf" value="0.08" />
    <xacro:property name="Abd2Hip_xb" value="-0.08" />
    <xacro:property name="Abd2Hip_yl" value="0.05" />
    <xacro:property name="Abd2Hip_yr" value="-0.05" />

    <xacro:property name="Hip2con_l" value="-0.06" />
    <xacro:property name="Hip2con_r" value="0.06" />


    <xacro:property name="Hip2K_l" value="0.06" />
    <xacro:property name="Hip2K_r" value="-0.06" />

    <xacro:property name="Knee2Foot_l" value="0.0" />
    <xacro:property name="Knee2Foot_r" value="0" />
    <!-- Hip-Abduction motor joint + offset( 5 cm) -->
    <joint name="joint_8" type="revolute">
        <parent link="abd0"/>
        <child link="hip0"/>
        <axis xyz="1 0 0"/>
        <!-- <origin xyz="0.08 0.05 0.0"/> -->
        <origin xyz="${Abd2Hip_xf} ${Abd2Hip_yl} 0.0"/> 
        <limit effort="40" lower="-0.707" upper="0.707" velocity="8"/>
        <dynamics damping="0.0" friction="0.0"/>
    </joint>



    <!-- Abduction joint. Joint names are: 8 9 10 11 -->
    <!-- Adding x offset to the joint -->
    <!-- y-origin point changed to 4.5 cm instead of 7 cm -->
    <joint name="joint_14" type="fixed">
        <parent link="front_body"/>
        <child link="abd0"/>
        <axis xyz="1 0 0"/>
        <!-- <origin xyz="0.1055 0.045 0"/> -->
        <origin xyz="${Abd_xf} ${Abd_yl} 0"/>
        <limit effort="40" lower="-0.707" upper="0.707" velocity="8"/>
        <dynamics damping="0.0" friction="0.0"/>
    </joint>


    

    <!-- Hip to Con -->
    <joint name="joint_20" type="fixed">
        <parent link="hip0"/>
        <child link="con0"/>
        <axis xyz="1 0 0"/>
        <origin xyz="0 ${Hip2con_l} 0"/>
        
        <dynamics damping="0.0" friction="0.0"/>
    </joint>

    <!-- Transmission elements required for Gazebo -->
    <transmission name="transmission_8">
        <type>transmission_interface/SimpleTransmission</type>
        <joint name="joint_8">
        <!-- <hardwareInterface>hardware_interface/EffortJointInterface</hardwareInterface> -->
        </joint>
        <actuator name="motor_8">
        <!-- <hardwareInterface>EffortJointInterface</hardwareInterface> -->
        <mechanicalReduction>1</mechanicalReduction>
        </actuator>
    </transmission>
    
    <!-- Upper leg -->
    <xacro:upper_leg name="upper0"/>

    <!-- Hip joint. (Motor to upper leg). Joint names are: 0 2 4 6 . Added Off-set in y-->
    <joint name="joint_0" type="revolute">
        <parent link="hip0"/>
        <child link="upper0"/>
        <axis xyz="0 -1 0"/>
        <origin xyz="0 ${Hip2K_l} 0"/>
        <!--  rpy="0 -0.3 0" -->
        <limit effort="40" lower="-6.28318530718" upper="6.28318530718" velocity="8"/>
        <dynamics damping="0.0" friction="0.0"/>
    </joint>
    <!-- Transmission elements required for Gazebo -->
    <transmission name="transmission_0">
        <type>transmission_interface/SimpleTransmission</type>
        <joint name="joint_0">
        <!-- <hardwareInterface>hardware_interface/EffortJointInterface</hardwareInterface> -->
        </joint>
        <actuator name="motor_0">
        <!-- <hardwareInterface>EffortJointInterface</hardwareInterface> -->
        <mechanicalReduction>1</mechanicalReduction>
        </actuator>
    </transmission>


    <!-- Lower leg -->
    <xacro:lower_leg name="lower0"/>
    <!-- Knee joint. Joint names are: 1 3 5 7 . Off-set added in y-->
    <joint name="joint_1" type="revolute">
        <parent link="upper0"/>
        <child link="lower0"/>
        <axis xyz="0 1 0"/>
        <origin xyz="-0.206 ${Knee2Foot_l} 0"/>
        <!--rpy="0 0.5 0"-->
        <limit effort="40" lower="0" upper="3.14159265359" velocity="8"/>
        <dynamics damping="0.0" friction="0.0"/>
    </joint>
    <!-- Transmission elements required for Gazebo -->
    <transmission name="transmission_1">
        <type>transmission_interface/SimpleTransmission</type>
        <joint name="joint_1">
        <!-- <hardwareInterface>hardware_interface/EffortJointInterface</hardwareInterface> -->
        </joint>
        <actuator name="motor_1">
        <!-- <hardwareInterface>EffortJointInterface</hardwareInterface> -->
        <mechanicalReduction>1.5</mechanicalReduction>
        <!-- Spirit knees have a 1.5 reduction from the original modules-->
        </actuator>
    </transmission>
    <!-- Toe -->
    <link name="toe0">
        <contact>
        <friction_anchor/>
        <stiffness value="30000.0"/>
        <damping value="1000.0"/>
        <spinning_friction value="0.3"/>
        <lateral_friction value="50.0"/>
        </contact>
        <visual>
        <origin rpy="0 0 0" xyz="0 0 0"/>
        <geometry>
            <sphere radius="0.02"/>
        </geometry>
        <material name="black"/>
        </visual>
        <collision>
        <origin rpy="0 0 0" xyz="0 0 0"/>
        <geometry>
            <sphere radius="0.02"/>
        </geometry>
        </collision>
        <inertial>
        <mass value="0.015"/>
        <inertia ixx="0.000025" ixy="0" ixz="0" iyy="0.000025" iyz="0" izz="0.000025"/>
        <!-- <inertia ixx="2/5*${toeMass}*${toeRadius}*${toeRadius}"  ixy="0"  ixz="0" iyy="2/5*${toeMass}*${toeRadius}*${toeRadius}" iyz="0" izz="2/5*${toeMass}*${toeRadius}*${toeRadius}" /> -->
        </inertial>
    </link>
    <joint name="jtoe0" type="fixed">
        <parent link="lower0"/>
        <child link="toe0"/>
        <origin xyz="0.206 0 -0.0"/>
        <dynamics damping="0.0" friction="0.0"/>
    </joint> 

  

 

  


   <!-- Hip motor -->
    <xacro:motor_left roll= "1.570796326795" pitch="0" yaw="0" name="hip1" color="yellow"/>  
    <!-- Abd motor -->
    <xacro:motor_left pitch= "1.570796326795" roll="0" yaw="0" name="abd1" color="copper"/>  

    <!-- Con motor -->
    <xacro:motor_left roll= "1.570796326795" pitch="0" yaw="0" name="con1" color="copper"/>  
  <!-- Hip-Abduction motor joint + offset -->
  <joint name="joint_9" type="revolute"> 
    <parent link="abd1"/>
    <child link="hip1"/>
    <axis xyz="1 0 0"/>
    <origin xyz="${Abd2Hip_xb} ${Abd2Hip_yl} 0.0"/> 
    <limit effort="40" lower="-0.707" upper="0.707" velocity="8"/>
    <dynamics damping="0.0" friction="0.0"/>
  </joint>


  <!-- Abduction joint. Joint names are: 8 9 10 11 -->
  <!-- y-origin point changed to 4.5 cm instead of 7 cm -->
  <joint name="abd2fb" type="fixed">
    <parent link="rear_body"/>
    <child link="abd1"/>
    <axis xyz="1 0 0"/>
    <!-- <origin xyz="-0.1055 0.045 0"/> -->
    <origin xyz="${Abd_xb} ${Abd_yl} 0"/>
    <limit effort="40" lower="-0.707" upper="0.707" velocity="8"/>
    <dynamics damping="0.0" friction="0.0"/>
  </joint>
  <!-- Transmission elements required for Gazebo -->
  <transmission name="transmission_9">
    <type>transmission_interface/SimpleTransmission</type>
    <joint name="joint_9">
      <!-- <hardwareInterface>hardware_interface/EffortJointInterface</hardwareInterface> -->
    </joint>
    <actuator name="motor_9">
      <!-- <hardwareInterface>EffortJointInterface</hardwareInterface> -->
      <mechanicalReduction>1</mechanicalReduction>
    </actuator>
  </transmission>


  <!-- Hip to Con -->
  <joint name="joint_20" type="fixed">
    <parent link="hip1"/>
    <child link="con1"/>
    <axis xyz="1 0 0"/>
    <origin xyz="0 ${Hip2con_l} 0"/>
    
    <dynamics damping="0.0" friction="0.0"/>
  </joint>

  <!-- Upper leg -->
  <xacro:upper_leg name="upper1"/>

  <!-- Hip joint. (Motor to upper leg). Joint names are: 0 2 4 6 . Added Off-set in y-->
  <joint name="joint_2" type="revolute">
    <parent link="hip1"/>
    <child link="upper1"/>
    <axis xyz="0 -1 0"/>
    <origin xyz="0 ${Hip2K_l} 0"/>
    <!--  rpy="0 -0.3 0" -->
    <limit effort="40" lower="-6.28318530718" upper="6.28318530718" velocity="8"/>
    <dynamics damping="0.0" friction="0.0"/>
  </joint>
  <!-- Transmission elements required for Gazebo -->
  <transmission name="transmission_2">
    <type>transmission_interface/SimpleTransmission</type>
    <joint name="joint_2">
      <!-- <hardwareInterface>hardware_interface/EffortJointInterface</hardwareInterface> -->
    </joint>
    <actuator name="motor_2">
      <!-- <hardwareInterface>EffortJointInterface</hardwareInterface> -->
      <mechanicalReduction>1</mechanicalReduction>
    </actuator>
  </transmission>
  <!-- Lower leg -->
  <xacro:lower_leg name="lower1"/>
  <!-- Knee joint. Joint names are: 1 3 5 7 . Off-set added in y-->
  <joint name="joint_3" type="revolute">
    <parent link="upper1"/>
    <child link="lower1"/>
    <axis xyz="0 1 0"/>
    <origin xyz="-0.206 ${Knee2Foot_l} 0"/>
    <!--rpy="0 0.5 0"-->
    <limit effort="40" lower="0" upper="3.14159265359" velocity="8"/>
    <dynamics damping="0.0" friction="0.0"/>
  </joint>
  <!-- Transmission elements required for Gazebo -->
  <transmission name="transmission_3">
    <type>transmission_interface/SimpleTransmission</type>
    <joint name="joint_3">
      <!-- <hardwareInterface>hardware_interface/EffortJointInterface</hardwareInterface> -->
    </joint>
    <actuator name="motor_3">
      <!-- <hardwareInterface>EffortJointInterface</hardwareInterface> -->
      <mechanicalReduction>1.5</mechanicalReduction>
      <!-- Spirit knees have a 1.5 reduction from the original modules-->
    </actuator>
  </transmission>
  <!-- Toe -->
  <link name="toe1">
    <contact>
      <friction_anchor/>
      <stiffness value="30000.0"/>
      <damping value="1000.0"/>
      <spinning_friction value="0.3"/>
      <lateral_friction value="50.0"/>
    </contact>
    <visual>
      <origin rpy="0 0 0" xyz="0 0 0"/>
      <geometry>
        <sphere radius="0.02"/>
      </geometry>
      <material name="black"/>
    </visual>
    <collision>
      <origin rpy="0 0 0" xyz="0 0 0"/>
      <geometry>
        <sphere radius="0.02"/>
      </geometry>
    </collision>
    <inertial>
      <mass value="0.015"/>
      <inertia ixx="0.000025" ixy="0" ixz="0" iyy="0.000025" iyz="0" izz="0.000025"/>
      <!-- <inertia ixx="2/5*${toeMass}*${toeRadius}*${toeRadius}"  ixy="0"  ixz="0" iyy="2/5*${toeMass}*${toeRadius}*${toeRadius}" iyz="0" izz="2/5*${toeMass}*${toeRadius}*${toeRadius}" /> -->
    </inertial>
  </link>
  <joint name="jtoe1" type="fixed">
    <parent link="lower1"/>
    <child link="toe1"/>
    <origin xyz="0.206 0 -0.0"/>
    <dynamics damping="0.0" friction="0.0"/>
  </joint>



   <!-- Hip motor -->
    <xacro:motor_right roll= "1.570796326795" pitch="0" yaw="0" name="hip2" color="yellow"/>  
    <!-- Abd motor -->
    <xacro:motor_right pitch= "1.570796326795" roll="0" yaw="0" name="abd2" color="copper"/>  

    <!-- Con motor -->
    <xacro:motor_right roll= "1.570796326795" pitch="0" yaw="0" name="con2" color="copper"/>  

  <!-- Hip-Abduction motor joint + offset -->
  <joint name="joint_10" type="revolute">
    <parent link="abd2"/>
    <child link="hip2"/>
    <axis xyz="1 0 0"/>
    <origin xyz="${Abd2Hip_xf} ${Abd2Hip_yr} 0.0"/> 
    <limit effort="40" lower="-0.707" upper="0.707" velocity="8"/>
    <dynamics damping="0.0" friction="0.0"/>
  </joint>

  <!-- Abduction joint. Joint names are: 8 9 10 11 -->
  <!-- y-origin point changed to 4.5 cm instead of 7 cm -->
  <joint name="joint_17" type="fixed">
    <parent link="front_body"/>
    <child link="abd2"/>
    <axis xyz="1 0 0"/>
    <!-- <origin xyz="0.1055 -0.045 0"/> -->
    <origin xyz="${Abd_xf} ${Abd_yr} 0"/>
    <limit effort="40" lower="-0.707" upper="0.707" velocity="8"/>
    <dynamics damping="0.0" friction="0.0"/>
  </joint>

  

  <!-- Hip to Con -->
  <joint name="joint_22" type="fixed">
    <parent link="hip2"/>
    <child link="con2"/>
    <axis xyz="1 0 0"/>
    <origin xyz="0 ${Hip2con_r} 0"/>
    
    <dynamics damping="0.0" friction="0.0"/>
  </joint>
  <!-- Transmission elements required for Gazebo -->
  <transmission name="transmission_10">
    <type>transmission_interface/SimpleTransmission</type>
    <joint name="joint_10">
      <!-- <hardwareInterface>hardware_interface/EffortJointInterface</hardwareInterface> -->
    </joint>
    <actuator name="motor_10">
      <!-- <hardwareInterface>EffortJointInterface</hardwareInterface> -->
      <mechanicalReduction>1</mechanicalReduction>
    </actuator>
  </transmission>
  <!-- Upper leg -->
  <xacro:upper_leg name="upper2"/>


  <!-- Hip joint. (Motor to upper leg). Joint names are: 0 2 4 6 . Added Off-set in y-->
  <joint name="joint_4" type="revolute">
    <parent link="hip2"/>
    <child link="upper2"/>
    <axis xyz="0 -1 0"/>
    <origin xyz="0 ${Hip2K_r} 0"/>
    <!--  rpy="0 -0.3 0" -->
    <limit effort="40" lower="-6.28318530718" upper="6.28318530718" velocity="8"/>
    <dynamics damping="0.0" friction="0.0"/>
  </joint>
  <!-- Transmission elements required for Gazebo -->
  <transmission name="transmission_4">
    <type>transmission_interface/SimpleTransmission</type>
    <joint name="joint_4">
      <!-- <hardwareInterface>hardware_interface/EffortJointInterface</hardwareInterface> -->
    </joint>
    <actuator name="motor_4">
      <!-- <hardwareInterface>EffortJointInterface</hardwareInterface> -->
      <mechanicalReduction>1</mechanicalReduction>
    </actuator>
  </transmission>
  <!-- Lower leg -->
  <xacro:lower_leg name="lower2"/>

  <!-- Knee joint. Joint names are: 1 3 5 7 . Off-set added in y-->
  <joint name="joint_5" type="revolute">
    <parent link="upper2"/>
    <child link="lower2"/>
    <axis xyz="0 1 0"/>
    <origin xyz="-0.206 ${Knee2Foot_r} 0"/>
    <!--rpy="0 0.5 0"-->
    <limit effort="40" lower="0" upper="3.14159265359" velocity="8"/>
    <dynamics damping="0.0" friction="0.0"/>
  </joint>
  <!-- Transmission elements required for Gazebo -->
  <transmission name="transmission_5">
    <type>transmission_interface/SimpleTransmission</type>
    <joint name="joint_5">
      <!-- <hardwareInterface>hardware_interface/EffortJointInterface</hardwareInterface> -->
    </joint>
    <actuator name="motor_5">
      <!-- <hardwareInterface>EffortJointInterface</hardwareInterface> -->
      <mechanicalReduction>1.5</mechanicalReduction>
      <!-- Spirit knees have a 1.5 reduction from the original modules-->
    </actuator>
  </transmission>
  <!-- Toe -->
  <link name="toe2">
    <contact>
      <friction_anchor/>
      <stiffness value="30000.0"/>
      <damping value="1000.0"/>
      <spinning_friction value="0.3"/>
      <lateral_friction value="50.0"/>
    </contact>
    <visual>
      <origin rpy="0 0 0" xyz="0 0 0"/>
      <geometry>
        <sphere radius="0.02"/>
      </geometry>
      <material name="black"/>
    </visual>
    <collision>
      <origin rpy="0 0 0" xyz="0 0 0"/>
      <geometry>
        <sphere radius="0.02"/>
      </geometry>
    </collision>
    <inertial>
      <mass value="0.015"/>
      <inertia ixx="0.000025" ixy="0" ixz="0" iyy="0.000025" iyz="0" izz="0.000025"/>
      <!-- <inertia ixx="2/5*${toeMass}*${toeRadius}*${toeRadius}"  ixy="0"  ixz="0" iyy="2/5*${toeMass}*${toeRadius}*${toeRadius}" iyz="0" izz="2/5*${toeMass}*${toeRadius}*${toeRadius}" /> -->
    </inertial>
  </link>
  <joint name="jtoe2" type="fixed">
    <parent link="lower2"/>
    <child link="toe2"/>
    <origin xyz="0.206 0 -0.0"/>
    <dynamics damping="0.0" friction="0.0"/>
  </joint>


   <!-- Hip motor -->
    <xacro:motor_right roll= "1.570796326795" pitch="0" yaw="0" name="hip3" color="yellow"/>  
    <!-- Abd motor -->
    <xacro:motor_right pitch= "1.570796326795" roll="0" yaw="0" name="abd3" color="copper"/>  

    <!-- Con motor -->
    <xacro:motor_right roll= "1.570796326795" pitch="0" yaw="0" name="con3" color="copper"/>  
  <!-- Hip-Abduction motor joint + offset -->
  <joint name="joint_11" type="revolute">
    <parent link="abd3"/>
    <child link="hip3"/>
    <axis xyz="1 0 0"/>
    <origin xyz="${Abd2Hip_xb} ${Abd2Hip_yr} 0.0"/> 
    <limit effort="40" lower="-0.707" upper="0.707" velocity="8"/>
    <dynamics damping="0.0" friction="0.0"/>
  </joint>

  <!-- Abduction joint. Joint names are: 8 9 10 11 -->
  <!-- changed y-origin to 4.5cm instead of 7 cm -->
  <joint name="abd2rb" type="fixed">
    <parent link="rear_body"/>
    <child link="abd3"/>
    <axis xyz="1 0 0"/>
    <!-- <origin xyz="-0.1055 -0.045 0"/> -->
    <origin xyz="${Abd_xb} ${Abd_yr} 0"/>
    <limit effort="40" lower="-0.707" upper="0.707" velocity="8"/>
    <dynamics damping="0.0" friction="0.0"/>
  </joint>
  <!-- Transmission elements required for Gazebo -->
  <transmission name="transmission_11">
    <type>transmission_interface/SimpleTransmission</type>
    <joint name="joint_11">
      <!-- <hardwareInterface>hardware_interface/EffortJointInterface</hardwareInterface> -->
    </joint>
    <actuator name="motor_11">
      <!-- <hardwareInterface>EffortJointInterface</hardwareInterface> -->
      <mechanicalReduction>1</mechanicalReduction>
    </actuator>
  </transmission>
  
  

  <!-- Hip to Con -->
  <joint name="joint_22" type="fixed">
    <parent link="hip3"/>
    <child link="con3"/>
    <axis xyz="1 0 0"/>
    <origin xyz="0 ${Hip2con_r} 0"/>
    
    <dynamics damping="0.0" friction="0.0"/>
  </joint>



  <!-- Upper leg -->
  <xacro:upper_leg name="upper3"/>

  <!-- Hip joint. (Motor to upper leg). Joint names are: 0 2 4 6 . Added Off-set in y-->
  <joint name="joint_6" type="revolute">
    <parent link="hip3"/>
    <child link="upper3"/>
    <axis xyz="0 -1 0"/>
    <origin xyz="0 ${Hip2K_r} 0"/>
    <!--  rpy="0 -0.3 0" -->
    <limit effort="40" lower="-6.28318530718" upper="6.28318530718" velocity="8"/>
    <dynamics damping="0.0" friction="0.0"/>
  </joint>
  <!-- Transmission elements required for Gazebo -->
  <transmission name="transmission_6">
    <type>transmission_interface/SimpleTransmission</type>
    <joint name="joint_6">
      <!-- <hardwareInterface>hardware_interface/EffortJointInterface</hardwareInterface> -->
    </joint>
    <actuator name="motor_6">
      <!-- <hardwareInterface>EffortJointInterface</hardwareInterface> -->
      <mechanicalReduction>1</mechanicalReduction>
    </actuator>
  </transmission>
  <!-- Lower leg -->
  <xacro:lower_leg name="lower3"/>


  <!-- Knee joint. Joint names are: 1 3 5 7 . Off-set added in y-->
  <joint name="joint_7" type="revolute">
    <parent link="upper3"/>
    <child link="lower3"/>
    <axis xyz="0 1 0"/>
    <origin xyz="-0.206 ${Knee2Foot_r} 0"/>
    <!--rpy="0 0.5 0"-->
    <limit effort="40" lower="0" upper="3.14159265359" velocity="8"/>
    <dynamics damping="0.0" friction="0.0"/>
  </joint>
  <!-- Transmission elements required for Gazebo -->
  <transmission name="transmission_7">
    <type>transmission_interface/SimpleTransmission</type>
    <joint name="joint_7">
      <!-- <hardwareInterface>hardware_interface/EffortJointInterface</hardwareInterface> -->
    </joint>
    <actuator name="motor_7">
      <!-- <hardwareInterface>EffortJointInterface</hardwareInterface> -->
      <mechanicalReduction>1.5</mechanicalReduction>
      <!-- Spirit knees have a 1.5 reduction from the original modules-->
    </actuator>
  </transmission>
  <!-- Toe -->
  <link name="toe3">
    <contact>
      <friction_anchor/>
      <stiffness value="30000.0"/>
      <damping value="1000.0"/>
      <spinning_friction value="0.3"/>
      <lateral_friction value="50.0"/>
    </contact>
    <visual>
      <origin rpy="0 0 0" xyz="0 0 0"/>
      <geometry>
        <sphere radius="0.02"/>
      </geometry>
      <material name="black"/>
    </visual>
    <collision>
      <origin rpy="0 0 0" xyz="0 0 0"/>
      <geometry>
        <sphere radius="0.02"/>
      </geometry>
    </collision>
    <inertial>
      <mass value="0.015"/>
      <inertia ixx="0.000025" ixy="0" ixz="0" iyy="0.000025" iyz="0" izz="0.000025"/>
      <!-- <inertia ixx="2/5*${toeMass}*${toeRadius}*${toeRadius}"  ixy="0"  ixz="0" iyy="2/5*${toeMass}*${toeRadius}*${toeRadius}" iyz="0" izz="2/5*${toeMass}*${toeRadius}*${toeRadius}" /> -->
    </inertial>
  </link>
  <joint name="jtoe3" type="fixed">
    <parent link="lower3"/>
    <child link="toe3"/>
    <origin xyz="0.206 0 -0.0"/>
    <dynamics damping="0.0" friction="0.0"/>
  </joint>
</robot>
